# Manejo de Excepciones y Gestión de Errores en Kotlin

El manejo de excepciones es un aspecto fundamental de la programación moderna, y Kotlin proporciona mecanismos concisos y poderosos para lidiar con varios escenarios que pueden llevar a errores. Exploremos los principios, técnicas y mejores prácticas para el manejo de excepciones en Kotlin.

## Entendiendo las Excepciones en Kotlin

Las excepciones son eventos que ocurren durante la ejecución de un programa que interrumpen el flujo normal de instrucciones. Estos pueden variar desde errores en tiempo de ejecución, como dividir por cero, hasta problemas como fallos de red. En Kotlin, las excepciones son objetos derivados de la clase `Throwable`. El objetivo principal del manejo de excepciones es gestionar de manera elegante estas situaciones inesperadas, evitando que la aplicación se bloquee y proporcionando a los desarrolladores información sobre la causa raíz del problema.

### Ejemplo 1: Lanzando una Excepción
```kotlin
// Función que lanza una excepción
fun dividir(a: Int, b: Int): Int {
    if (b == 0) {
        throw IllegalArgumentException("No se puede dividir por cero")
    }
    return a / b
}
```
En este ejemplo, la función `dividir` lanza una `IllegalArgumentException` si el divisor (`b`) es cero.

### Ejemplo 2: Manejando una Excepción
```kotlin
// Manejando la excepción lanzada por la función dividir
fun divisionSegura(a: Int, b: Int): Int {
    return try {
        dividir(a, b)
    } catch (e: IllegalArgumentException) {
        println("Excepción capturada: ${e.message}")
        -1
    }
}
```
La función `divisionSegura` utiliza un bloque `try-catch` para manejar la excepción lanzada por la función `dividir`. Si ocurre una excepción, imprime el mensaje y devuelve un valor predeterminado.

## El Bloque Try-Catch: Protegiendo Tu Código

El bloque `try-catch` es una construcción fundamental en Kotlin para manejar excepciones. Te permite encapsular código que podría lanzar una excepción y definir cómo manejar tipos específicos de excepciones.

### Ejemplo 3: Try-Catch Básico
```kotlin
// Función con un bloque try-catch
fun operacionSegura(valor: String): Int {
    return try {
        valor.toInt()
    } catch (e: NumberFormatException) {
        println("Conversión fallida: ${e.message}")
        -1
    }
}
```
Aquí, la función `operacionSegura` intenta convertir una cadena a un entero usando `toInt()`. Si la conversión falla (por ejemplo, debido a una cadena no numérica), se captura y maneja una `NumberFormatException`.

### Ejemplo 4: Manejando Múltiples Excepciones
```kotlin
// Función con múltiples bloques catch
fun parsearEntrada(entrada: String): Int {
    return try {
        entrada.toInt()
    } catch (e: NumberFormatException) {
        println("Formato de número inválido: ${e.message}")
        -1
    } catch (e: NullPointerException) {
        println("La entrada es nula: ${e.message}")
        -1
    }
}
```
La función `parsearEntrada` demuestra cómo manejar múltiples excepciones teniendo bloques catch separados para `NumberFormatException` y `NullPointerException`.

### Ejemplo 5: Bloque Finally
```kotlin
// Función con un bloque finally
fun leerDeArchivo(nombreArchivo: String): String {
    return try {
        // Código para leer del archivo
        "Contenido del archivo"
    } catch (e: IOException) {
        println("Error al leer el archivo: ${e.message}")
        "Contenido predeterminado"
    } finally {
        println("Cerrando recursos")
        // Código para cerrar recursos (por ejemplo, manejadores de archivos)
    }
}
```
En este ejemplo, la función `leerDeArchivo` tiene un bloque `finally`, asegurando que los recursos se cierren independientemente de si ocurre una excepción o no.

## La Expresión Throw: Personalizando Mensajes de Error

En Kotlin, la expresión `throw` te permite lanzar explícitamente una excepción. Esto puede ser útil cuando deseas manejar una condición de error específica o comunicar un mensaje de error personalizado.

### Ejemplo 6: Excepción Personalizada
```kotlin
// Clase de excepción personalizada
class ExcepcionEntradaInvalida(mensaje: String) : Exception(mensaje)

// Función que usa la expresión throw
fun procesarEntrada(entrada: String) {
    if (entrada.isBlank()) {
        throw ExcepcionEntradaInvalida("La entrada no puede estar en blanco")
    }
    // Procesar la entrada
}
```
Aquí, la clase `ExcepcionEntradaInvalida` es una excepción personalizada, y la función `procesarEntrada` usa la expresión `throw` para lanzar esta excepción cuando la entrada está en blanco.

### Ejemplo 7: Propagando Excepciones
```kotlin
// Función que propaga excepciones
fun procesarArchivo(nombreArchivo: String): String {
    return try {
        // Código para leer del archivo
        "Contenido del archivo"
    } catch (e: IOException) {
        println("Error al leer el archivo: ${e.message}")
        throw ExcepcionProcesamientoArchivo("El procesamiento del archivo falló")
    }
}
```
La función `procesarArchivo` propaga una excepción capturando una `IOException` y luego lanzando una excepción personalizada (`ExcepcionProcesamientoArchivo`).

## El Tipo `Nothing` de Kotlin: Representando Expresiones No Terminantes

Kotlin tiene un tipo especial llamado `Nothing`, que representa valores que nunca existen o funciones que nunca retornan normalmente (es decir, lanzan una excepción).

### Ejemplo 8: Función que Retorna Nothing
```kotlin
// Función que retorna Nothing
fun fallo(mensaje: String): Nothing {
    throw IllegalStateException(mensaje)
}
```
La función `fallo` retorna el tipo `Nothing`, indicando que nunca completa normalmente y siempre lanza una excepción.

### Ejemplo 9: Uso de Nothing en el Manejo de Excepciones
```kotlin
// Función que maneja una excepción y retorna Nothing
fun hacerAlgoRiesgoso() {
    val resultado = try {
        // Operación riesgosa
        fallo("Operación fallida")
    } catch (e: IllegalStateException) {
        println("Excepción capturada: ${e.message}")
        // Continuar con una alternativa segura
        "Alternativa segura"
    }
    println("Resultado: $resultado")
}
```
Aquí, `hacerAlgoRiesgoso` usa la función `fallo` que retorna `Nothing` en el bloque `try`. El bloque catch maneja la excepción, y la función continúa con una alternativa segura.

## Excepciones Verificadas vs. No Verificadas en Kotlin

Kotlin distingue entre excepciones verificadas y no verificadas. Las excepciones no verificadas (heredan de `RuntimeException`) no requieren manejo explícito, mientras que las excepciones verificadas (heredan de `Exception` pero no de `RuntimeException`) deben ser manejadas o declaradas.

### Ejemplo 10: Excepción No Verificada
```kotlin
// Excepción no verificada (RuntimeException)
fun excepcionNoVerificada() {
    throw IllegalStateException("Esta es una excepción no verificada")
}
```
Aquí, `excepcionNoVerificada` lanza una `IllegalStateException`, una excepción no verificada.

### Ejemplo 11: Excepción Verificada
```kotlin
// Excepción verificada (no RuntimeException)
fun excepcionVerificada() {
    throw IOException("Esta es una excepción verificada")
}
```
Por otro lado, `excepcionVerificada` lanza una `IOException`, una excepción verificada.

## El Operador Elvis: Simplificando las Comprobaciones de Nulos

En Kotlin, el operador Elvis (`?:`) es una forma concisa de manejar valores nulos y proporcionar un valor predeterminado o una acción alternativa cuando se encuentra un nulo.

### Ejemplo 12: Usando el Operador Elvis
```kotlin
// Función que usa el operador Elvis
fun longitudOZero(entrada: String?): Int {
    return entrada?.length ?: 0
}
```
La función `longitudOZero` retorna la longitud de la cadena de entrada o cero si la entrada es nula, gracias al operador Elvis.

### Ejemplo 13: Combinando con la Expresión Throw
```kotlin
// Función que usa el operador Elvis con la expresión throw
fun requerirNoNulo(entrada: String?): String {
    return entrada ?: throw IllegalArgumentException("La entrada no debe ser nula")
}
```
Aquí, `requerirNoNulo` usa el operador Elvis para verificar si hay nulos y lanza una `IllegalArgumentException` con un mensaje personalizado si la entrada es nula.

## Corutinas y Manejo de Excepciones

Las corutinas de Kotlin introducen una nueva dimensión en el manejo de excepciones en código asincrónico. Las corutinas proporcionan una forma estructurada de manejar excepciones dentro de bloques de código asincrónico.

### Ejemplo 14: Manejo de Excepciones en Corutinas
```kotlin
import kotlinx.coroutines.*

// Función de corutina con manejo de excepciones
suspend fun obtenerDatos(): String {
    return try {
        // Simular una solicitud de red
        delay(1000)
        "¡Datos obtenidos!"
    } catch (e: Exception) {
        println("Excepción durante la obtención de datos: ${e.message}")
        "Datos predeterminados"
    }
}
```
En este ejemplo, la corutina `obtenerDatos` simula una solicitud de red y usa un bloque `try-catch` para manejar excepciones que podrían ocurrir durante la operación asincrónica.

### Ejemplo 15: Usando el Manejo de Excepciones en Corutinas
```kotlin
// Usando la función de corutina con manejo de excepciones
fun main() {
    runBlocking {
        val resultado = async { obtenerDatos() }
        println("Resultado de la corutina: ${resultado.await()}")
    }
}
```
La función `main` usa el constructor de corutinas `runBlocking` para ejecutar la corutina asincrónica `obtenerDatos`. El resultado se imprime, mostrando cómo se pueden manejar las excepciones en corutinas.

## Mejores Prácticas para el Manejo de Excepciones

A medida que navegas por el panorama del manejo de excepciones en Kotlin, considera estas mejores prácticas para mejorar la robustez y mantenibilidad de tu código:
1. **Sé Específico en el Manejo de Excepciones:** Captura excepciones específicas en lugar de usar una `Exception` genérica. Esto te permite manejar diferentes excepciones de manera adecuada.
2. **Maneja Excepciones Cerca de la Fuente:** Idealmente, captura excepciones lo más cerca posible de la fuente, donde tienes el contexto y la información para manejarlas de manera efectiva.
3. **Registra Detalles de Excepciones:** Registra detalles relevantes sobre las excepciones para ayudar en la depuración y resolución de problemas. Asegúrate de que tus registros sean informativos y proporcionen información sobre la causa de la excepción.
4. **Usa Excepciones Personalizadas con Moderación:** Introduce excepciones personalizadas cuando sea necesario para comunicar condiciones de error específicas. Esto mejora la legibilidad y claridad del código.
5. **Falla Rápidamente:** Si surge una condición de error, falla rápidamente lanzando una excepción temprano en el proceso. Esto evita la propagación de estados inesperados y potencialmente dañinos.
6. **Limpia Recursos en el Bloque Finally:** Si tu código involucra recursos que necesitan ser liberados, usa el bloque `finally` para asegurar una limpieza adecuada, incluso en presencia de excepciones.
7. **Diseña para la Recuperación:** Al manejar excepciones, considera estrategias de recuperación o mecanismos de respaldo para manejar errores de manera elegante y mantener la estabilidad de tu aplicación.
8. **Prueba Unitaria de Escenarios de Excepción:** Incluye pruebas unitarias que cubran varios escenarios de excepción. Esto asegura que tu código se comporte como se espera frente a errores.